Workbook

Sheet Catálogo
A1: RC · Catálogo de Questionários — Ricardina Correia · OPP 8233
A2: Cada coluna tem filtro (seta no cabeçalho). Para idade: filtre «Idade min <= X» e «Idade max >= X». | Idade min 0 = desde o nascimento; Idade max 99 = sem limite superior. | Adicionar instrumento: ver folha «Como atualizar».
A3: Nº | B3: Nome do Instrumento | C3: Área Clínica | D3: Destinatários | E3: Faixa etária | F3: Idade mín (anos) | G3: Idade máx (anos) | H3: Nº domínios | I3: Objetivo clínico | J3: Domínios / Subescalas (por extenso) | K3: syncKey (Sheet) | L3: ID interno | M3: Link
A4: =ROW()-3 -> 1 | B4: ABAS-3 — Auto-relato | C4: Neurodesenvolvimento | D4: Paciente | E4: 16–89 anos | F4: 16 | G4: 99 | H4: 4 | I4: Avalia comportamento adaptativo — auto-relato (16–89 anos) | J4: Compósito Adaptativo Geral (GAC); Domínio Conceptual (CC); Domínio Social (SC); Domínio Prático (PC) | K4: abas3_adult | L4: q_abas3_adult | M4: https://correiaricardina-ui.github.io/questionarios/ABAS3_Autorrelato_v1.html
A5: =ROW()-3 -> 2 | B5: ABAS-3 — Educador (0–5) | C5: Neurodesenvolvimento | D5: Educador(a) | E5: 0–5 anos | F5: 0 | G5: 5.9 | H5: 4 | I5: Avalia comportamento adaptativo — versão educador (0–5 anos) | J5: Compósito Adaptativo Geral (CAG); Domínio Conceptual (CC); Domínio Social (SC); Domínio Prático (PC) | K5: abas3_05p | L5: q_abas3_05p | M5: https://correiaricardina-ui.github.io/questionarios/ABAS3_PreEscolar_Educador.html
A6: =ROW()-3 -> 3 | B6: ABAS-3 — Pais/Cuid. (>6) | C6: Neurodesenvolvimento | D6: Mãe, Pai, Enc. Educação | E6: 6–21 anos | F6: 6 | G6: 20.9 | H6: 4 | I6: Avalia comportamento adaptativo — versão pais/cuidadores (>6 anos) | J6: Compósito Adaptativo Geral (CAG); Domínio Conceptual (CC); Domínio Social (SC); Domínio Prático (PC) | K6: abas3_pais | L6: q_abas3_pais | M6: https://correiaricardina-ui.github.io/questionarios/ABAS3_Pais_v2.html
A7: =ROW()-3 -> 4 | B7: ABAS-3 — Pais/Cuid. (0–5) | C7: Neurodesenvolvimento | D7: Mãe, Pai, Enc. Educação | E7: 0–5 anos | F7: 0 | G7: 5.9 | H7: 4 | I7: Avalia comportamento adaptativo — versão pais (0–5 anos) | J7: Compósito Adaptativo Geral (CAG); Domínio Conceptual (CC); Domínio Social (SC); Domínio Prático (PC) | K7: abas3_05 | L7: q_abas3_05 | M7: https://correiaricardina-ui.github.io/questionarios/ABAS3_PreEscolar.html
A8: =ROW()-3 -> 5 | B8: ABAS-3 — Professor (>6) | C8: Neurodesenvolvimento | D8: Professor(a) | E8: 6–21 anos | F8: 6 | G8: 20.9 | H8: 4 | I8: Avalia comportamento adaptativo — versão professor (>6 anos) | J8: Compósito Adaptativo Geral (CAG); Domínio Conceptual (CC); Domínio Social (SC); Domínio Prático (PC) | K8: abas3_prof | L8: q_abas3_prof | M8: https://correiaricardina-ui.github.io/questionarios/ABAS3_Professor_v2.html
A9: =ROW()-3 -> 6 | B9: Anamnese — História Prévia | C9: Anamnese, História & Monitorização | D9: Mãe, Pai, Enc. Educação | E9: 0–18 anos | F9: 0 | G9: 83.2 | H9: 5 | I9: Recolha qualitativa de história clínica, desenvolvimento, familiar, escolar e relacional prévia à consulta | J9: História Clínica; Desenvolvimento; Estrutura Familiar; História Escolar; Relacionamentos | K9: anamnese_hp | L9: q_anamnese_hp | M9: https://correiaricardina-ui.github.io/questionarios/Anamnese_HP_v1.html
A10: =ROW()-3 -> 7 | B10: Anamnese Complementar | C10: Anamnese, História & Monitorização | D10: Mãe, Pai, Enc. Educação | E10: 0–18 anos | F10: 0 | G10: 83.2 | H10: 4 | I10: Recolher história clínica, desenvolvimento e funcionamento quotidiano | J10: História Clínica; Desenvolvimento Precoce; Funcionamento Executivo; Regulação Emocional | K10: anamnese_complementar | L10: q_anamnese | M10: https://correiaricardina-ui.github.io/questionarios/Anamnese_complementar_v2.html
A11: =ROW()-3 -> 8 | B11: Anamnese Parental Complementar | C11: Anamnese, História & Monitorização | D11: Mãe, Pai, Enc. Educação | E11: Todas as idades | F11: 0 | G11: 99 | H11: 5 | I11: Recolha estruturada da perspetiva do progenitor ou cuidador que não esteve presente na consulta de anamnese inicial e deseja integrar o processo de avaliação/intervenção. Instrumento qualitativo de anamnese — sem cotação: regista motivação para participar, preocupação principal e áreas assinaladas, a criança no contexto do respondente (rotinas, o que corre bem, o que é mais difícil), evolução percebida, informação adicional e expectativas/disponibilidade. | J11: Preocupações principais; Áreas assinaladas; Contexto do respondente; Evolução percebida; Expectativas e disponibilidade | K11: anamnese_parental_complementar | L11: q_anamnese_parental_complementar | M11: https://correiaricardina-ui.github.io/questionarios/ANAMNESE_PARENTAL_COMPLEMENTAR_v1.html
A12: =ROW()-3 -> 9 | B12: AQ Buss-Perry — Agressividade | C12: Externalização & Comportamento | D12: Paciente | E12: Adultos (≥16 anos) | F12: 16 | G12: 99 | H12: 5 | I12: Auto-relato (29 itens, ~5-8 min) para avaliação multidimensional da agressividade (Buss & Perry, 1992; adaptação portuguesa Cunha & Gonçalves, 2012, n=633 universitários). Quatro subescalas: Agressividade Física (AF, 9 itens), Agressividade Verbal (AV, 5 itens), Raiva/Ira (7 itens), Hostilidade (HO, 8 itens) + Total AQ. Escala Likert 1-5. Itens 9 e 16 invertidos. Classificação em 4 níveis por sexo (Baixa, Média, Elevada, Muito Elevada). Aviso técnico: a subescala Agressividade Verbal tem consistência interna baixa (α=.56) — interpretar com prudência. Os domínios não são visíveis ao paciente durante o preenchimento. | J12: Agressividade Física (AF); Agressividade Verbal (AV); Raiva/Ira; Hostilidade (HO); Total AQ | K12: aq_bussperry | L12: q_aq_bussperry | M12: https://correiaricardina-ui.github.io/questionarios/AQ_BussPerry_v1.html
A13: =ROW()-3 -> 10 | B13: AQ-Child — Quociente de Espectro do Autismo (Versão Criança) | C13: Neurodesenvolvimento | D13: Mãe, Pai, Enc. Educação | E13: 4–11 anos | F13: 4 | G13: 11.9 | H13: 6 | I13: Rastreio de traços do espectro do autismo em crianças (Auyeung, Baron-Cohen, Wheelwright & Allison, 2008; tradução portuguesa Coelho, 2020). Preenchimento por pais/cuidadores · 50 itens · escala Likert 4 pontos (Concordo plenamente · Concordo · Discordo · Discordo totalmente). 24 itens directos + 26 itens reversos. Cinco subescalas (10 itens cada): Habilidades Sociais (S), Atenção Alternante (A), Atenção aos Detalhes (D), Comunicação (C), Imaginação (I). Total = 0–150. Cut-off clínico ≥ 76 (Sens. 95% · Espec. 95%). Médias normativas: controlos M=41,7 (DP=18,6); SA/AAF M=104,8 (DP=15,6); autismo M=103,0 (DP=16,3). Instrumento de triagem — não substitui avaliação clínica nem confere diagnóstico. | J13: Habilidades Sociais (S); Atenção Alternante (A); Atenção aos Detalhes (D); Comunicação (C); Imaginação (I); Total | K13: aqchild | L13: q_aq_child | M13: https://correiaricardina-ui.github.io/questionarios/AQ_Child_v1.html
A14: =ROW()-3 -> 11 | B14: ASEBA — CBCL 1½-5 | C14: Externalização & Comportamento | D14: Pais, Mãe, Pai, Enc. Educação | E14: 1½–5 anos | F14: 1.5 | G14: 5.9 | H14: 10 | I14: Avaliar problemas emocionais e comportamentais em idade pré-escolar | J14: Internalizante; Externalizante; Total; Reatividade Emocional; Ansiedade; Queixas Somáticas; Retraimento; Problemas de Sono; Problemas de Atenção; Comportamento Agressivo | K14: cbcl15 | L14: q_cbcl_15 | M14: https://correiaricardina-ui.github.io/questionarios/CBCL_15_v5.html
A15: =ROW()-3 -> 12 | B15: ASEBA — CBCL 6-18 | C15: Externalização & Comportamento | D15: Pais, Mãe, Pai, Enc. Educação | E15: 6–18 anos | F15: 6 | G15: 17.9 | H15: 10 | I15: Avaliar problemas emocionais e comportamentais | J15: Internalizante; Externalizante; Total; Ansiedade/Depressão; Queixas Somáticas; Isolamento; Problemas Sociais; Problemas de Atenção; Comportamento Agressivo; Comportamento de Quebra de Regras | K15: cbcl | L15: q_aseba_cbcl | M15: https://correiaricardina-ui.github.io/questionarios/CBCL_618_v1.html
... A155: =ROW()-3 -> 152 | B155: UCLA-PTSD Adaptado — Rastreio de PSPT Pediátrica | C155: Trauma & Stress | D155: Aplicador clínico | E155: 7–11 anos (estendível 3–18) | F155: 3 | G155: 17.9 | H155: 13 | I155: Instrumento clínico ad-hoc (sem validação psicométrica formal — uso orientativo, articulado com entrevista clínica). Adaptação inspirada (Via B do protocolo) operacionalizando os critérios A–H do DSM-5-TR para Perturbação de Stress Pós-Traumático pediátrica, com formulação original em português europeu — NÃO constitui reprodução do UCLA PTSD Reaction Index for DSM-5 (Steinberg, Brymer, Pynoos et al.). Cotação clínica integrativa por psicólogo. Estrutura em 8 módulos: M1 Exposição (Critério A — 13 tipos de eventos sim/não + idade na altura), Evento Índice (tipo, idade, modalidade, descrição), M2 Intrusão (5 itens B Likert 0-4), M3 Evitamento (2 itens C), M4 Cognição/humor (7 itens D), M5 Ativação (6 itens E), M6 Dissociação (2 itens — especificador), M7 Duração F + Início H em meses, M8 Interferência funcional G (5 domínios). Total sintomático = B+C+D+E (0-80). Bandas: Mínima 0-19 / Ligeira 20-34 / Moderada 35-49 / Severa 50-80. Regra DSM-5-TR cumprida = A+B+C+D+E+F+G todos positivos. Especificadores: dissociativo (Dis1 ou Dis2 ≥ 2) e expressão tardia (início ≥ 6 meses). Padrões T1-T5 com hipótese clínica e ação sugerida. Não substitui o UCLA PTSD-RI, o CAPS-CA-5 ou outros instrumentos validados. | J155: Exposição (Critério A); Evento Índice; Intrusão (B); Evitamento (C); Cognição/humor (D); Ativação (E); Dissociação (especificador); Duração e Início (F, H); Interferência funcional (G); Total sintomático; Banda; Padrão T1–T5; Regra DSM-5-TR | K155: ucla_ptsd_adaptado | L155: q_ucla_ptsd_adaptado | M155: https://correiaricardina-ui.github.io/questionarios/UCLA_PTSD_Adaptado.html
A156: 153 | B156: CSHQ-PT — Hábitos de Sono da Criança (Pais) | C156: Sono | D156: Mãe, Pai, Enc. Educação | E156: 2–10 anos | F156: 2 | G156: 10.9 | H156: 9 | I156: Rastreio dos hábitos e problemas de sono por heteroavaliação parental (33 itens, escala de frequência). Cotação em 8 subescalas + Índice de Perturbação do Sono (IPS). Ponto de corte da validação portuguesa: IPS ≥ 48 = rastreio positivo (Silva et al., 2013). Rastreio, não diagnóstico. | J156: Resistência em ir para a cama; Início do sono; Duração do sono; Ansiedade associada ao sono; Despertares noturnos; Parassónias; Perturbação respiratória do sono; Sonolência diurna; Índice de Perturbação do Sono (IPS) | K156: cshq_pt_pais | L156: q_cshq_pt_pais | M156: https://correiaricardina-ui.github.io/questionarios/CSHQ_PT_Pais_v1.html
A157: 154 | B157: SSR-PT — Auto-Relato sobre o Sono | C157: Sono | D157: Paciente | E157: 7–12 anos | F157: 7 | G157: 12.9 | H157: 8 | I157: Auto-relato dos hábitos e problemas de sono (itens cotados 4–26, escala de frequência). Cotação em 7 subescalas + Total SSR. Cut-off Total > 41 = perturbação global do sono (Owens et al., 2000). Rastreio, não diagnóstico; integrar com relato parental (ex. CSHQ-PT). | J157: Resistência ao Deitar; Início do Sono; Duração do Sono; Ansiedade do Sono; Despertares Noturnos; Parassónias; Sonolência Diurna; Total SSR | K157: ssr_pt | L157: q_ssr_pt | M157: https://correiaricardina-ui.github.io/questionarios/SSR_PT_v1.html
A158: 155 | B158: TS-OC · Parte I — Gravidade de Tiques (YGTSS) | C158: Neurodesenvolvimento | D158: Mãe, Pai, Enc. Educação, Paciente | E158: 6–18 anos | F158: 6 | G158: 18.9 | H158: 5 | I158: Lista de sintomas de tiques + escala de gravidade (Yale Global Tic Severity Scale; Leckman et al., 1989). Cotação descritiva das dimensões motora e fónica em duas janelas — Atual (últimos 7 dias) e Pior fase — com Total de Tiques (0–50), Comprometimento (0–50) e Pontuação Global (0–100). Aplicação com apoio familiar; cotação final confirmada pelo/a psicólogo/a em entrevista. Rastreio/monitorização, não diagnóstico. | J158: Subtotal Motor; Subtotal Fónico; Total de Tiques; Comprometimento; Pontuação Global YGTSS | K158: tsoc_ygtss | L158: q_tsoc_ygtss | M158: https://correiaricardina-ui.github.io/questionarios/TSOC_YGTSS_v1.html
A159: 156 | B159: A-DES — Escala de Experiências Dissociativas em Adolescentes | C159: Trauma & Stress | D159: Paciente | E159: 11–18 anos | F159: 11 | G159: 18 | H159: 6 | I159: Rastreio dimensional de experiências dissociativas por auto-relato do adolescente (30 itens, escala 0–10). Métrica = média global + 5 domínios (Amnésia; Despersonalização/Desrealização; Absorção; Alteração de Identidade; Transversal). Ponto de corte orientador: média ≥ 4,0 = dissociação clinicamente significativa; 3,0–3,9 = moderada. Instrumento de rastreio/orientação, não diagnóstico — integrar sempre com entrevista clínica, observação e história de vida. | J159: Amnésia; Despersonalização/Desrealização; Absorção; Alteração de Identidade; Transversal; Média Global A-DES | K159: ades | L159: q_ades | M159: https://correiaricardina-ui.github.io/questionarios/A_DES_v1.html
A160: =ROW()-3 -> 157 | B160: ACE-Q — Experiências Adversas na Infância · Autorrelato (Adolescente) | C160: Trauma & Stress | D160: Paciente | E160: 12–18 anos | F160: 12 | G160: 18 | H160: 6 | I160: Rastreio de experiências adversas na infância por autorrelato do adolescente (18 itens, escala de frequência 0–2). Adaptação clínica da ACE-Q (Felitti et al., 1998) / ACE-IQ (WHO, 2010) para 6 domínios. Pontuação total 0–36 com bandas orientadoras (0–8 baixa; 9–18 moderada; >18 elevada) e classificação por domínio. Instrumento de rastreio/orientação, não diagnóstico — integrar sempre com entrevista clínica e história de vida. Os domínios e a pontuação não são visíveis ao respondente. | J160: Relações familiares e ambiente emocional; Instabilidade familiar; Experiências de perda; Experiências de insegurança ou ameaça; Experiências sociais difíceis; Experiência emocional interna | K160: aceq_adol | L160: q_aceq_adol | M160: https://correiaricardina-ui.github.io/questionarios/ACE-Q_Adolescente.html
A161: =ROW()-3 -> 158 | B161: ACE-Q — Experiências Adversas na Infância · Cuidador | C161: Trauma & Stress | D161: Mãe, Pai, Enc. Educação | E161: 0–18 anos | F161: 0 | G161: 18 | H161: 6 | I161: Rastreio de experiências adversas na infância por relato do cuidador (15 itens, escala de frequência 0–2). Adaptação clínica da ACE-Q (Felitti et al., 1998) e da versão pediátrica PEARLS (Brar et al., 2021) para 6 domínios. Pontuação total 0–30 com bandas orientadoras (0–6 baixa exposição; 7–14 moderada; ≥15 significativa) e classificação por domínio. Instrumento de rastreio/orientação, não diagnóstico — integrar sempre com entrevista clínica e história de vida. Os domínios e a pontuação não são visíveis ao respondente. | J161: Ambiente emocional familiar; Instabilidade familiar; Experiências de perda; Segurança e proteção; Experiências sociais difíceis; Eventos stressantes significativos | K161: aceq_cuid | L161: q_aceq_cuid | M161: https://correiaricardina-ui.github.io/questionarios/ACE-Q_Cuidador.html
A162: =ROW()-3 -> 159 | B162: Entrevista adaptada CAARMS — Experiências Psicóticas Atenuadas, Dissociação e Funcionamento | C162: Risco, Autolesão & Psicopatologia Geral | D162: Psicóloga (aplicação clínica) | E162: Adolescentes / jovens | F162: 11 | G162: 99 | H162: 11 | I162: Entrevista semiestruturada aplicada pela psicóloga (Avaliação Fenomenológica de Experiências Psicóticas Atenuadas, Dissociação e Funcionamento Subjetivo). Adaptação inspirada (Via B) nos domínios do CAARMS (Yung, McGorry et al., 2005), com formulação original em português europeu — NÃO constitui reprodução do CAARMS. Orientadora e descritiva, não diagnóstica: não classifica risco (UHR/APS/BLIPS). 10 domínios com cotação estruturada 0/1/2 (típico–preservado / intermédio / marcado–ausente); campos vazios cotam 0. A aplicação regista as respostas fluidas ditas pelo próprio, a cotação de cada item e observações qualitativas; o painel apresenta o perfil por domínio, o Índice Global de Alteração Dimensional (IGAD = média dos 10 índices; IGAD bruto = soma/54×100) e um painel de sinalização (11 marcadores Alto/Médio). Bandas orientadoras do IGAD: <34 Mínima / 34–66 Moderada / ≥67 Elevada. Instrumento orientativo, a integrar sempre com entrevista clínica, observação e história de vida. Os domínios e a pontuação não são visíveis ao respondente. | J162: Experiências percetivas atípicas; Pensamento, fluência e organização cognitiva; Ideias de referência, desconfiança e hipervigilância; Self, corpo e experiências dissociativas; Experiência emocional e afetividade; Funcionamento global e esforço subjetivo; Narrativa subjetiva e organização do discurso; Qualidade de contacto e presença relacional; Insight, significado e medos implícitos; Coerência interna e continuidade do self; IGAD (Índice Global de Alteração Dimensional) | K162: caarms_adap | L162: q_caarms_adap | M162: https://correiaricardina-ui.github.io/questionarios/Entrevista_CAARMS_adap.html
A163: =ROW()-3 -> 160 | B163: Prova «O Cuidar e a Integridade do Corpo» | C163: Trauma & Stress | D163: Psicóloga (aplicação clínica) | E163: Idade escolar (≈ 6–11 anos) | F163: 6 | G163: 11 | H163: 4 | I163: Prova projetiva integrada de story-stems abertos (instrumento original de Ricardina Correia, 2026), de aplicação exclusiva pela psicóloga, para avaliação idiográfica e qualitativa do cuidar, da integridade corporal, do coping e das figuras cuidadoras em idade escolar (≈6–11 anos). Administração não-diretiva: não nomear «medo/dor/doença/hospital» antes da criança; sondas condicionais só se o tema emergir; registo do verbatim, hesitações, evitamentos e pedidos de tranquilização; desenho opcional. Leitura descritiva (não-normativa, não-cotação): posicionamento 1 (adaptativo) → 5 (vulnerabilidade) nos eixos, mais reparação relacional no desfecho. Instrumento orientativo, a integrar sempre com entrevista clínica, observação e história de vida. Os eixos e o posicionamento não são visíveis ao respondente. | J163: Integridade corporal; Cuidado e dependência; Coping / resolução (padrão predominante + secundário); Figuras cuidadoras (+ reparação relacional no desfecho) | K163: cuidar_corpo | L163: q_cuidar_corpo | M163: https://correiaricardina-ui.github.io/questionarios/Prova_Cuidar_Integridade_Corpo_v1.html
A164: =ROW()-3 -> 161 | B164: CSAS — Escala de Ansiedade de Separação para Crianças (Criança) | C164: Ansiedade, Depressão & Internalização | D164: Paciente | E164: 8–11 anos | F164: 8 | G164: 11 | H164: 5 | I164: Autorrelato de sintomas de ansiedade de separação (20 itens, 4 fatores). Corte total ≥ 68 orientativo (norma espanhola, não portuguesa; Méndez et al., 2014). | J164: Preocupação com a separação (cognitivo); Mal-estar da separação (psicofisiológico); Oposição à separação (comportamental); Calma na separação (fator positivo, invertido no cálculo — itens 3, 8, 12, 15, 19); Total (20–100) | K164: csas | L164: q_csas | M164: https://correiaricardina-ui.github.io/questionarios/CSAS_v1.html
A165: =ROW()-3 -> 162 | B165: CSAS-P — Escala de Ansiedade de Separação para Crianças · Versão Pais | C165: Ansiedade, Depressão & Internalização | D165: Mãe, Pai, Enc. Educação | E165: 8–11 anos | F165: 8 | G165: 11 | H165: 5 | I165: Heterorrelato parental de ansiedade de separação (20 itens, 4 fatores). Sem ponto de corte; leitura principal por fator (z vs norma parental espanhola, não portuguesa; Méndez et al., 2022). | J165: Preocupação; Oposição; Calma (fator positivo/protetor — leitura inversa); Mal-estar (norma com efeito de chão — ler com cautela); Total orientativo = Preocupação + Oposição + Mal-estar + (30 − Calma) | K165: csas_p | L165: q_csas_p | M165: https://correiaricardina-ui.github.io/questionarios/CSAS_P_v1.html
A166: =ROW()-3 -> 163 | B166: SGRS — Sohn Grayson Rating Scale | C166: Neurodesenvolvimento | D166: Mãe, Pai, Enc. Educação, Professor(a), Educador(a), Psicóloga | E166: 3–18 anos | F166: 3 | G166: 18 | H166: 7 | I166: Rastreio e sistematização da observação de comportamentos associados a PEA de alto funcionamento (Sohn & Grayson, 2005). 58 itens · 6 domínios · Likert 1–4 (1 = Não é verdade · 2 = Raramente · 3 = Às vezes · 4 = Frequentemente) · SEM itens invertidos · amplitude 58–232 (o mínimo é 58 e não 0). Admite pais, professor e clínico em paralelo — o painel calcula a concordância inter-informantes (amplitude entre médias/item: ≥1,00 discrepância assinalável · ≥0,50 ligeira). Total bruto só é válido com 58/58 itens; com omissos apresenta estimativa prorrateada (média/item × 58), rotulada como exploratória. NÃO existem normas portuguesas — versão portuguesa é tradução de trabalho, sem adaptação transcultural nem validação psicométrica. Bandas globais dos autores (58–89 Muito baixa · 90–118 Baixa · 119–149 Média a moderada · 150–177 Moderada a alta · 178–207 Alta a muito alta · 208–232 Muito alta), sem derivação empírica publicada nem estudos independentes de fidelidade/validade/sensibilidade/especificidade. Classificação por domínio = convenção descritiva sem base normativa (média/item: 1,00–1,74 mínima · 1,75–2,49 ligeira · 2,50–3,24 moderada · 3,25–4,00 elevada) — PENDENTE DE RATIFICAÇÃO. Instrumento de rastreio: não estabelece nem exclui diagnóstico de PEA e não substitui avaliação diagnóstica multimodal. Terminologia original («Síndrome de Asperger», «PDD de alto funcionamento») é anterior ao DSM-5-TR/CID-11 — reportar em nomenclatura atual (PEA com especificadores de gravidade). Cautelas: Discurso e Linguagem pesa 38 % dos itens (22/58); Comportamento Motor tem só 2 itens (média instável); itens G02 (memorização) e L13 (vocabulário) descrevem competências mas são cotados na mesma direção. | J166: Comportamento Social (14 itens; 14–56) — amizades, iniciativa de jogo, jogo imaginativo e repetitivo, contacto ocular, expressões faciais/linguagem corporal, multidões, perspetiva do outro, compreensão e expressão emocional, espaço pessoal, regras de jogo; Comportamento (8 itens; 8–32) — medos incomuns, interesses obsessivos/ritualismo, pensamento dicotómico, hábitos alimentares, comportamentos persistentes, rigidez a mudanças/transições, perfecionismo, ansiedade; Discurso e Linguagem (22 itens; 22–88) — uso peculiar de palavras, não pedir explicação/ajuda, humor e provocações, iniciar e manter conversa recíproca, interesse pelo outro, discurso adultificado, comentários embaraçosos, perguntas e tópicos obsessivos, vocabulário, linguagem social, pronomes, prosódia/volume, linguagem em scripts, literalidade, ideia principal, rituais verbais, gestos, manutenção do tópico; Cognição (7 itens; 7–28) — conceitos abstratos, memorização, motricidade fina, literalidade do comportamento dos outros, generalização da aprendizagem, distratibilidade, atenção sustentada; Perceção Sensorial (5 itens; 5–20) — sensibilidade invulgar a ruídos, cheiros, paladares, texturas e toque; Comportamento Motor (2 itens; 2–8) — movimentos repetidos/estereotipados, dificuldades motoras; Pontuação Global (58–232) — bandas de probabilidade dos autores. | K166: sgrs | L166: q_sgrs | M166: https://correiaricardina-ui.github.io/questionarios/SGRS_v1.html
A167: =ROW()-3 -> 164 | B167: AIS-8 — Escala de Insónia de Atenas | C167: Sono | D167: Paciente | E167: ≥ 12 anos | F167: 12 | G167: 99 | H167: 5 | I167: Rastreio de insónia clinicamente significativa e monitorização da evolução (Soldatos, Dikeos & Paparrigopoulos, 2000, 2003). Autorrelato, 8 itens, escala ordinal 0–3, período de referência: último mês. Estrutura em dois blocos: itens 1–5 sono noturno (AIS-5) e itens 6–8 consequências diurnas. Todos os itens directos — sem itens invertidos e sem ponderações; total = soma dos 8 itens (0–24). Ponto de corte total ≥ 6 (sensibilidade 93%, especificidade 85%, 90% de classificação correta; regressão logística contra diagnóstico CID-10 de insónia não orgânica, amostra clínica adulta grega — NÃO validado em adolescentes). Bandas descritivas de gravidade de Okajima et al. (2020), critério ISI, amostra comunitária adulta japonesa — estatuto descritivo/exploratório. NÃO existem normas portuguesas e a formulação PT-PT dos itens não corresponde a uma versão portuguesa validada: comparações com dados normativos internacionais exigem reserva. Instrumento de rastreio e monitorização — não estabelece diagnóstico isoladamente: um resultado abaixo do ponto de corte não exclui perturbação do sono e um resultado acima não a confirma. Em adolescentes, integrar sempre com hábitos, rotinas e higiene do sono, ansiedade e ruminação pré-sono, impacto escolar e emocional, e discrepâncias pais ↔ autorrelato; quando indicado, complementar com diário de sono e avaliação médica. | J167: Índice noturno — AIS-5 (itens 1–5; 0–15) — sintomatologia noturna: dificuldade em adormecer (indução), despertares durante a noite (manutenção), acordar mais cedo do que desejado (despertar final), duração total do sono e qualidade global do sono; Índice diurno (itens 6–8; 0–9) — repercussão diurna: sensação de bem-estar durante o dia, funcionamento diário (atenção, energia, desempenho) e sonolência durante o dia; Total AIS-8 (0–24) — soma directa dos 8 itens; Banda descritiva de gravidade — 0–5 Ausência de insónia · 6–9 Insónia ligeira · 10–15 Insónia moderada · 16–24 Insónia grave (Okajima et al., 2020; leitura exploratória em adolescentes); Rastreio (ponto de corte ≥ 6) — positivo/negativo face ao ponto de corte de Soldatos et al. (2003). Indicadores auxiliares descritivos, sem estatuto diagnóstico: nº de itens com resposta ≥ 2 (extensão da sintomatologia) e nº de itens com resposta = 3 (intensidade máxima referida); perfil dimensional por comparação da % do máximo entre índice noturno e índice diurno (diferença ≥ 20 pontos percentuais = predomínio relativo). | K167: ais8 | L167: q_ais8 | M167: https://correiaricardina-ui.github.io/questionarios/AIS_8_v1.html
A168: =ROW()-3 -> 165 | B168: GAD-7 — Escala de Ansiedade Generalizada | C168: Ansiedade, Depressão & Internalização | D168: Paciente | E168: ≥ 12 anos | F168: 12 | G168: 99 | H168: 4 | I168: Rastreio da gravidade sintomática de ansiedade generalizada e monitorização da evolução (Spitzer, Kroenke, Williams & Löwe, 2006). Autorrelato, 7 itens, escala ordinal 0–3, período de referência: últimos 14 dias; aplicação individual ou coletiva em 2–3 minutos; heteroaplicação admissível em caso de limitação de literacia, registando-se essa condição. Instrumento UNIDIMENSIONAL: total = soma directa dos 7 itens (0–21), sem subescalas, sem itens invertidos e sem ponderações (ACP em Sousa et al., 2015; AFE em Leite & Faro, 2022, 62,8% de variância explicada) — os agrupamentos de conteúdo são meramente descritivos e não têm estatuto psicométrico. Ponto de corte operacional ≥ 10 (Spitzer et al., 2006: sensibilidade 89%, especificidade 82%). Bandas de gravidade descritiva 0–4 · 5–9 · 10–14 · 15–21 da amostra original norte-americana, replicadas na literatura subsequente. NÃO EXISTEM NORMAS PORTUGUESAS (percentis ou pontuações padronizadas): os limiares 5/10/15 são bandas descritivas e não limiares diagnósticos — «Ansiedade grave» descreve intensidade sintomática, não é atribuição nosológica. A validação portuguesa de referência (Sousa et al., 2015; artigo em acesso aberto CC-BY) foi conduzida em amostra clínica psiquiátrica adulta (78,8% mulheres, idade média 52,2 anos) — a generalização a populações não clínicas, a outros escalões etários e a contexto pediátrico exige prudência; Gonçalves (2019, validação portuguesa 6–16 anos) reporta prevalência com base num valor superior a 11, não coincidente com o corte adulto de 10. Instrumento de RASTREIO: não constitui, por si, instrumento de diagnóstico e não substitui a entrevista clínica nem o exame do estado mental — um total elevado é inespecífico e sobrepõe-se a sintomatologia depressiva (r = 0,450 com a subescala de depressão da HADS) e um total baixo não exclui perturbação de ansiedade. Estatuto de acesso: VIA A — instrumento legalmente acessível, reproduzido com atribuição (família PHQ/GAD, autorização expressa de reprodução, tradução e distribuição). | J168: Total GAD-7 (0–21) — soma directa dos 7 itens; instrumento unidimensional, NÃO calcula subescalas. Banda de gravidade descritiva — 0–4 Ansiedade mínima (sintomatologia ansiosa ausente ou residual no período de referência) · 5–9 Ansiedade leve (intensidade ligeira, abaixo do limiar de rastreio) · 10–14 Ansiedade moderada (intensidade moderada, acima do limiar de rastreio) · 15–21 Ansiedade grave (intensidade elevada, acima do limiar de rastreio) — limiares de Spitzer et al. (2006), NÃO são normas portuguesas. Rastreio (ponto de corte ≥ 10) — positivo/negativo face ao ponto de corte operacional, editável. Validade do protocolo — regra de dados em falta (decisão interna documentada; a escala original não a define): itens não respondidos são excluídos do denominador e NUNCA cotados como zero (0 é resposta substantiva, «Nunca»); com 6 itens respondidos o total é estimado por prorata — ARRED(soma ÷ n × 7; 0) — e sinalizado como estimativa; com menos de 6 o protocolo é inválido e não é gerada interpretação. Indicadores auxiliares descritivos, sem estatuto diagnóstico: % da pontuação máxima; nº de itens com pontuação ≥ 2 (sintoma referido em mais de metade dos dias); item de pontuação mais elevada (o primeiro, em caso de empate). Agrupamentos de conteúdo MERAMENTE DESCRITIVOS (sem estatuto de subescala; sem cotação própria): apreensão/tensão nervosa (item 1); cognitivo — incontrolabilidade da preocupação (item 2); cognitivo — preocupação excessiva e multifocal (item 3); somático — tensão/dificuldade de relaxamento (item 4); somático-motor — inquietação (item 5); irritabilidade (item 6); apreensão antecipatória (item 7). Nota: a versão em uso omite o item 8 canónico (dificuldade causada pelos problemas), que não é cotado mas informa a apreciação da incapacidade funcional. | K168: gad7 | L168: q_gad7 | M168: https://correiaricardina-ui.github.io/questionarios/GAD7_v1.html
A169: =ROW()-3 -> 166 | B169: SMQ — Questionário de Mutismo Seletivo (Pais) | C169: Ansiedade, Depressão & Internalização | D169: Mãe, Pai, Enc. Educação | E169: 3–17 anos | F169: 3 | G169: 17 | H169: 10 | I169: Quantificação da frequência de fala por contexto, da interferência funcional associada e monitorização da mudança em resposta a intervenção (Bergman, Keller, Piacentini & Bergman, 2008). Relato parental, 23 itens. Itens 1–17: escala ordinal de frequência 0–3 (Nunca · Raramente · Frequentemente · Sempre), período de referência: últimas duas semanas; itens 18–23: escala de interferência/desconforto 0–3 (Nada · Um pouco · Moderadamente · Muito), que NÃO integra a pontuação de sintomas. ATENÇÃO — ESCALA INVERSA: pontuações mais BAIXAS indicam MENOR frequência de fala e, portanto, MAIOR gravidade sintomática. Métrica primária: média por escala (0–3); métrica secundária: soma prorrateada (média × nº nominal de itens). Os itens 12 e 17 admitem legitimamente «Não aplicável» (ausência de ama/cuidador; ausência de atividades extraescolares) e são excluídos de numerador e denominador. NÃO é instrumento de diagnóstico e não gera pontos de corte diagnósticos; não existem normas portuguesas — todos os limiares utilizados são exploratórios. Não discrimina de forma fiável o mutismo seletivo da perturbação de ansiedade social isolada. | J169: Escola (itens 1–6; média 0–3; N mín. 5 de 6; referência DT ≥ 2,50) — frequência de fala com colegas, professores e perante a turma. · Casa/Família (itens 7–12; N mín. 4 de 6; referência DT ≥ 2,50) — fala com familiares coabitantes e não coabitantes, ao telefone e com cuidadores; é estruturalmente a subescala menos afetada, pelo que valores baixos exigem reformulação da hipótese. · Social (itens 13–17; N mín. 3 de 5; referência DT ≈ 2,00, estruturalmente MAIS BAIXA — comparar contra 2,50 produziria sobreidentificação sistemática) — fala com desconhecidos, profissionais de saúde, funcionários e em atividades extraescolares. · TOTAL SMQ (itens 1–17; N mín. 13 de 17; invalidado se qualquer subescala não for cotada). · Escala de sintomas em métrica de soma (0–51) — rastreio: ≤ 14 positivo com especificidade máxima · ≤ 38 positivo (sensibilidade 100%, especificidade 74,3%) · > 38 negativo. ADVERTÊNCIA: o corte de 13 citado na literatura secundária refere-se à cotação INVERTIDA do estudo neerlandês e NÃO se aplica à cotação original — o equivalente correto é 38. · Interferência funcional na criança (itens 18–21; N mín. 3 de 4). · Desconforto da criança (item 22). · Desconforto do cuidador (item 23). · Índice global de interferência (itens 18–23; soma 0–18; escala autónoma, α = 0,81). · IDC — Índice de Discrepância Contextual (média Casa/Família − média Escola; construção própria; interpretável apenas com média Escola < 2,00; a classificação «Restrição extensiva ao contexto familiar» com média Casa < 1,50 tem precedência sobre a magnitude do IDC). · Discrepância Social − Escola. · Concordância inter-informante na subescala Escola (calculada automaticamente a partir da versão Professores do mesmo código: < 0,50 elevada · 0,50–0,99 moderada · ≥ 1,00 discrepância relevante). Bandas descritivas da média (0–3): 0–0,49 Fala ausente ou quase ausente · 0,50–0,99 Fala muito reduzida · 1,00–1,49 Fala reduzida · 1,50–1,99 Fala inconsistente · 2,00–2,49 Fala frequente · 2,50–3,00 Fala consistente. | K169: smq_pais | L169: q_smq_pais | M169: https://correiaricardina-ui.github.io/questionarios/SMQ_Pais_v1.html
A170: =ROW()-3 -> 167 | B170: SMQ — Questionário de Mutismo Seletivo (Professores) | C170: Ansiedade, Depressão & Internalização | D170: Professor(a), Educador(a) | E170: 3–17 anos | F170: 3 | G170: 17 | H170: 5 | I170: Quantificação da frequência de fala do aluno em contexto escolar e da interferência percebida pelo professor, com utilização preferencial na monitorização da mudança (Bergman, Keller, Piacentini & Bergman, 2008). Relato do professor/educador, 11 itens. Itens 1–6: escala ordinal de frequência 0–3 (Nunca · Raramente · Frequentemente · Sempre), período de referência: últimas duas semanas — conteúdos item a item idênticos aos itens 1–6 da versão parental, o que torna a comparação inter-informante metodologicamente limpa; itens a–e: escala de interferência/desconforto 0–3. ATENÇÃO — ESCALA INVERSA: pontuações mais BAIXAS indicam MENOR frequência de fala e MAIOR gravidade. LIMITE DE ALCANCE: esta versão contém 6 itens de frequência e 5 de interferência, diferindo do School Speech Questionnaire publicado — os resultados das duas versões NÃO são permutáveis, e o rastreio por métrica de soma (≤ 38/51) aplica-se exclusivamente à versão parental de 17 itens. Sozinha não estabelece o padrão situacional que define o mutismo seletivo (Critério A do DSM-5-TR), por observar um único contexto: exige a versão parental ao lado. | J170: Escola — professor (itens 1–6; média 0–3; soma prorrateada 0–18; N mín. 5 de 6; referência DT ≥ 2,50, aplicada por analogia à cotação escolar por professor) — fala com colegas próximos e com a maioria dos colegas, resposta a questões do professor, iniciativa de questionar, fala com professores e funcionários, e fala em grupo ou perante a turma. Âncoras clínicos: nas amostras clínicas de mutismo seletivo os valores de base situam-se consistentemente abaixo de 1,00 e, após intervenção, tipicamente entre 1 e 2; Bergman et al. (2008) reportaram valores ≥ 2,50 num pequeno grupo referenciado por outras perturbações de ansiedade (n = 18), o que sustenta a especificidade desta subescala. · Interferência funcional percebida (itens a–c; N mín. 2 de 3) — interferência na escola, nas situações sociais e na vida do aluno em geral. · Desconforto do aluno (item d). · Desconforto do próprio professor (item e) — reportado separadamente por não constituir o mesmo constructo. · Concordância inter-informante na subescala Escola (calculada automaticamente a partir da versão Pais do mesmo código; o professor observa o contexto diretamente, o relato parental sobre a escola é indireto: < 0,50 concordância elevada · 0,50–0,99 moderada · ≥ 1,00 discrepância relevante). NOTA: os itens de interferência NÃO são sobreponíveis entre versões (a parental tem 4 itens funcionais, incluindo relações familiares; esta tem 3), pelo que apenas a subescala Escola é comparada entre informantes. Bandas descritivas da média (0–3): 0–0,49 Fala ausente ou quase ausente · 0,50–0,99 Fala muito reduzida · 1,00–1,49 Fala reduzida · 1,50–1,99 Fala inconsistente · 2,00–2,49 Fala frequente · 2,50–3,00 Fala consistente. | K170: smq_prof | L170: q_smq_prof | M170: https://correiaricardina-ui.github.io/questionarios/SMQ_Professores_v1.html
A171: =ROW()-3 -> 168 | B171: QCVE-P — Comportamento Verbal em Contexto Escolar (Professor) | C171: Ansiedade, Depressão & Internalização | D171: Professor(a), Educador(a), Diretor(a) de Turma | E171: 3–18 anos | F171: 3 | G171: 18 | H171: 7 | I171: Mede a frequência do comportamento verbal do/a aluno/a em contexto escolar, desagregada por interlocutor e por grau de exposição comunicativa, na avaliação e no seguimento do mutismo seletivo. Instrumento ORIGINAL de Ricardina Correia (2026), Via B, inspirado no modelo estrutural do School Speech Questionnaire (Bergman, Piacentini & McCracken, 2002) — não é tradução nem adaptação autorizada, e não é permutável com o SMQ. Informante: docente com contacto regular. Janela: último mês. 8 a 12 minutos. ATENÇÃO: sem normas portuguesas — bandas exploratórias, de ancoragem analógica; instrumento de gravidade e de mudança, NÃO de diagnóstico. | J171: E1 — Comunicação verbal com pares (itens 1–4; média 0–3). E2 — Comunicação verbal com adultos da escola (itens 5–8; média 0–3). E3 — Comunicação verbal em situações de exposição (itens 9–12; média 0–3). Total ECV — média das três médias de subescala (0–3); ESCALA INVERSA: mais baixo = menos fala = maior gravidade; bandas 0,00–0,50 ausente ou vestigial · 0,51–1,00 muito restrito · 1,01–1,75 restrito · 1,76–2,49 parcialmente estabelecido · 2,50–3,00 ajustado ao contexto. IRV — Índice de Restrição Verbal (3 − Total ECV), orientado à gravidade. ICNV — Índice de Comunicação Não Verbal (itens 13–16; média 0–3), índice AUTÓNOMO, nunca somado à ECV. IIF — Índice de Interferência Funcional (itens 17–20; média 0–3), escala de direção INVERTIDA e índice AUTÓNOMO, nunca somado à ECV. Bloco contextual (Parte IV) não cotado, mas condicionante da validade da leitura. «SO» excluído do numerador e do denominador; subescala válida com ≥3 de 4 itens; com exactamente 3 marca estimativa exploratória; com ≤2 é INVÁLIDA e nunca cotada a zero. | K171: qcvep_prof | L171: q_qcvep_prof | M171: https://correiaricardina-ui.github.io/questionarios/QCVEP_Prof_v1.html
... A224: =ROW()-3 -> 221 | B224: EAFE-CA — Escala de Avaliação do Funcionamento Executivo em Crianças e Adolescentes (Professores) | C224: Atenção, PHDA & Funções Executivas | D224: Professor(a), Diretor(a) de turma | E224: 6–17 anos | F224: 6 | G224: 17 | H224: 16 | I224: Avalia o FUNCIONAMENTO EXECUTIVO no quotidiano em cinco domínios de autorregulação. Instrumento ORIGINAL de construção própria em português europeu, inspirado no modelo híbrido de autorregulação e funções executivas de Barkley (1997, 2011, 2012): NÃO constitui tradução, adaptação autorizada nem equivalente psicométrico de qualquer instrumento publicado. 60 itens em escala 1–4 (1 nunca ou raramente · 2 às vezes · 3 frequentemente · 4 muito frequentemente), janela dos ÚLTIMOS 6 MESES, 5 blocos paginados de 12 itens correspondentes aos 5 domínios. DEZ itens invertidos (8, 11, 18, 23, 31, 35, 42, 47, 53, 57), recodificados como 5 menos o valor assinalado — descrevem comportamentos ADEQUADOS e não dificuldades. ⚠ NÃO DISPÕE de estudos de validade, fidelidade ou normas para a população portuguesa: os limiares são CRITERIAIS, ancorados na escala de resposta, e NÃO normativos — leitura em paleta AZUL, sem codificação de gravidade por cores. ⚠ Apoio EXPLORATÓRIO à formulação clínica e à monitorização de intervenção; não substitui instrumentos validados (BRIEF, Conners, ASEBA) nem fundamenta, isoladamente, qualquer decisão diagnóstica. ⚠ O literal N/C (não cotável) é devolvido e gravado TAL COMO VEM quando um domínio tem menos de 10 itens respondidos, o protocolo global menos de 50, falta algum dos 10 itens do IRE ou falta alguma das cinco médias de domínio para a AID — N/C e zero são resultados clinicamente opostos. ⚠ AID igual ou superior a 0,75 obriga a interpretar POR DOMÍNIO e não pelo compósito global. ⚠ TRÊS FORMAS ISOMÓRFICAS (Pais e Cuidadores, Autorrelato, Professores), em que a mesma posição corresponde ao mesmo conteúdo, o que permite comparação directa item a item, por domínio e entre contextos; manter o MESMO informante ao longo dos momentos. ⚠ NÃO confundir com a EAFE (Entrevista de Análise Funcional do Estudo), instrumento distinto. Forma de HETERORRELATO ESCOLAR, com registo da disciplina leccionada, do tempo de conhecimento do aluno e do número de horas semanais de contacto — dados indispensáveis para ponderar a base observacional de quem responde. A comparação casa × escola é uma das saídas clinicamente mais produtivas: a especificidade contextual das dificuldades executivas orienta a formulação e o plano de acomodações. | J224: AGT · Autogestão do Tempo (itens 1–12): noção do tempo, estimativa de duração, antecipação, cumprimento de prazos e prontidão de material | ARP · Auto-organização e Resolução de Problemas (itens 13–24): memória de trabalho aplicada, sequenciação de etapas, flexibilidade perante o imprevisto, organização do material e organização do discurso | ACI · Autocontrolo Inibitório (itens 25–36): inibição de resposta, espera pela vez, ponderação das alternativas, avaliação do risco e ajustamento ao feedback correctivo | AMP · Automotivação e Persistência (itens 37–48): manutenção do esforço em tarefa monótona, resistência à distração, iniciativa em tarefa de rotina e trabalho para objetivos diferidos | ARE · Autorregulação Emocional (itens 49–60): tolerância à frustração, latência de recuperação, reavaliação depois de acalmar e interferência do estado emocional no desempenho | Por domínio: pontuação bruta, média por item (1,00–4,00) e CI (contagem de indicadores — itens corrigidos iguais ou superiores a 3); exige pelo menos 10 dos 12 itens respondidos, caso contrário devolve N/C | PEG · Pontuação Executiva Global: soma dos itens corrigidos respondidos; exige pelo menos 50 dos 60 itens | MEG · Média Executiva Global (1,00–4,00) = PEG a dividir pelo número de itens respondidos; métrica de leitura de eleição, comparável entre domínios, entre informantes e entre momentos | CI_Global · contagem global de indicadores (0–60): 0–11 sem indicadores · 12–20 ligeiros · 21–35 moderados · 36 ou mais acentuados | IRE · Índice de Risco Executivo (10–40) = soma dos itens 4, 6, 13, 19, 25, 28, 37, 44, 50 e 55; exige os 10 itens respondidos | AID · Amplitude Interdomínios = média mais alta menos média mais baixa; igual ou superior a 0,75 indica perfil HETEROGÉNEO e obriga a leitura por domínio | Limiares criteriais da média por item: 1,00–1,74 sem indicadores · 1,75–2,24 ligeiros · 2,25–2,99 moderados · 3,00–4,00 acentuados | Limiares criteriais do IRE: inferior a 25 sem sinalização · 25–29 sinalização moderada · 30 ou mais sinalização elevada | Matriz de leitura clínica domínio × categoria: para cada um dos cinco domínios e cada uma das quatro categorias, a orientação interpretativa e a indicação de aprofundamento ou de suporte correspondentes | Validade do protocolo: N_Respondidos (de 60), Opcoes_Distintas (de 4 — padrão de resposta pouco diferenciado), Disc_Media (média dos itens invertidos menos média dos directos — possível aquiescência ou itens invertidos não processados) e texto da Sinalização activa | Monitorização serial pelo campo Momento da avaliação, mantendo o MESMO informante ao longo dos momentos | K224: eafeca_t | L224: q_eafeca_t | M224: https://correiaricardina-ui.github.io/questionarios/EAFECA_Prof_v1.html

Sheet Resumo por Área
A1: Resumo por Área Clínica (recalcula automaticamente)
A2: Área Clínica | B2: Nº de instrumentos | C2: % do total
A3: Anamnese, História & Monitorização | B3: =COUNTIF(Catálogo!$C$4:$C$1000,A3) -> 5 | C3: =IF($B$21=0,0,B3/$B$21) -> 0.022624434
A4: Neurodesenvolvimento | B4: =COUNTIF(Catálogo!$C$4:$C$1000,A4) -> 27 | C4: =IF($B$21=0,0,B4/$B$21) -> 0.12217195
A5: Atenção, PHDA & Funções Executivas | B5: =COUNTIF(Catálogo!$C$4:$C$1000,A5) -> 21 | C5: =IF($B$21=0,0,B5/$B$21) -> 0.095022624
A6: Ansiedade, Depressão & Internalização | B6: =COUNTIF(Catálogo!$C$4:$C$1000,A6) -> 36 | C6: =IF($B$21=0,0,B6/$B$21) -> 0.16289593
A7: Risco, Autolesão & Psicopatologia Geral | B7: =COUNTIF(Catálogo!$C$4:$C$1000,A7) -> 10 | C7: =IF($B$21=0,0,B7/$B$21) -> 0.045248869
A8: Trauma & Stress | B8: =COUNTIF(Catálogo!$C$4:$C$1000,A8) -> 5 | C8: =IF($B$21=0,0,B8/$B$21) -> 0.022624434
A9: Externalização & Comportamento | B9: =COUNTIF(Catálogo!$C$4:$C$1000,A9) -> 10 | C9: =IF($B$21=0,0,B9/$B$21) -> 0.045248869
A10: Regulação Emocional & Coping | B10: =COUNTIF(Catálogo!$C$4:$C$1000,A10) -> 22 | C10: =IF($B$21=0,0,B10/$B$21) -> 0.099547511
A11: Alimentação & Imagem Corporal | B11: =COUNTIF(Catálogo!$C$4:$C$1000,A11) -> 10 | C11: =IF($B$21=0,0,B11/$B$21) -> 0.045248869
A12: Sono | B12: =COUNTIF(Catálogo!$C$4:$C$1000,A12) -> 5 | C12: =IF($B$21=0,0,B12/$B$21) -> 0.022624434
A13: Família & Parentalidade | B13: =COUNTIF(Catálogo!$C$4:$C$1000,A13) -> 26 | C13: =IF($B$21=0,0,B13/$B$21) -> 0.11764706
A14: Escola, Motivação & Aprendizagem | B14: =COUNTIF(Catálogo!$C$4:$C$1000,A14) -> 12 | C14: =IF($B$21=0,0,B14/$B$21) -> 0.054298643
... A20: Comportamentos Aditivos | B20: =COUNTIF(Catálogo!$C$4:$C$1000,A20) -> 1 | C20: =IF($B$21=0,0,B20/$B$21) -> 0.0045248869
A21: TOTAL CATALOGADO | B21: =COUNTA(Catálogo!$B$4:$B$1000) -> 221 | C21: =IF(B21=0,0,B21/B21) -> 1
A23: Soma por área = total catalogado? | B23: =IF(SUM(B3:B20)=B21,"OK","Existe ÁREA nova — acrescentar linha no resumo") -> OK
A24: Áreas fora do vocabulário canónico | B24: =IF(COUNTA(Catálogo!$C$4:$C$1000)-SUM(B3:B20)=0,"OK","Existe ÁREA fora das 18 canónicas") -> OK

Sheet Anamnese & História
A1: Anamnese, História & Monitorização | I1: =COUNTIF(Catálogo!$C$4:$C$1000,$A$1)&IF(COUNTIF(Catálogo!$C$4:$C$1000,$A$1)=1," instrumento nesta área"," instrumentos nesta área") -> 5 instrumentos nesta área
A2: Vista automática da folha «Catálogo». Não editar aqui: acrescente ou altere sempre na folha «Catálogo» e esta atualiza-se sozinha. | I2: =IF(COUNTIF(Catálogo!$C$4:$C$1000,$A$1)>12,"⚠ Área com mais instrumentos do que linhas nesta folha — alargar","OK") -> OK
A3: Nº | B3: Nome do Instrumento | C3: Área Clínica | D3: Destinatários | E3: Faixa etária | F3: Idade mín (anos) | G3: Idade máx (anos) | H3: Nº domínios | I3: Objetivo clínico | J3: Domínios / Subescalas (por extenso) | K3: syncKey (Sheet) | L3: ID interno | M3: Link
A4: =IFERROR(INDEX(Catálogo!A$4:A$1000,MATCH($A$1&"|"&1,Índice!$A$4:$A$1000,0)),"") -> 6 | B4: =IFERROR(INDEX(Catálogo!B$4:B$1000,MATCH($A$1&"|"&1,Índice!$A$4:$A$1000,0)),"") -> Anamnese — História Prévia | C4: =IFERROR(INDEX(Catálogo!C$4:C$1000,MATCH($A$1&"|"&1,Índice!$A$4:$A$1000,0)),"") -> Anamnese, História & Monitorização | D4: =IFERROR(INDEX(Catálogo!D$4:D$1000,MATCH($A$1&"|"&1,Índice!$A$4:$A$1000,0)),"") -> Mãe, Pai, Enc. Educação | E4: =IFERROR(INDEX(Catálogo!E$4:E$1000,MATCH($A$1&"|"&1,Índice!$A$4:$A$1000,0)),"") -> 0–18 anos | F4: =IFERROR(INDEX(Catálogo!F$4:F$1000,MATCH($A$1&"|"&1,Índice!$A$4:$A$1000,0)),"") -> 0 | G4: =IFERROR(INDEX(Catálogo!G$4:G$1000,MATCH($A$1&"|"&1,Índice!$A$4:$A$1000,0)),"") -> 83.2 | H4: =IFERROR(INDEX(Catálogo!H$4:H$1000,MATCH($A$1&"|"&1,Índice!$A$4:$A$1000,0)),"") -> 5 | ... M4: =IFERROR(INDEX(Catálogo!M$4:M$1000,MATCH($A$1&"|"&1,Índice!$A$4:$A$1000,0)),"") -> https://correiaricardina-ui.github.io/questionarios/Anamnese_HP_v1.html
A5: =IFERROR(INDEX(Catálogo!A$4:A$1000,MATCH($A$1&"|"&2,Índice!$A$4:$A$1000,0)),"") -> 7 | B5: =IFERROR(INDEX(Catálogo!B$4:B$1000,MATCH($A$1&"|"&2,Índice!$A$4:$A$1000,0)),"") -> Anamnese Complementar | C5: =IFERROR(INDEX(Catálogo!C$4:C$1000,MATCH($A$1&"|"&2,Índice!$A$4:$A$1000,0)),"") -> Anamnese, História & Monitorização | D5: =IFERROR(INDEX(Catálogo!D$4:D$1000,MATCH($A$1&"|"&2,Índice!$A$4:$A$1000,0)),"") -> Mãe, Pai, Enc. Educação | E5: =IFERROR(INDEX(Catálogo!E$4:E$1000,MATCH($A$1&"|"&2,Índice!$A$4:$A$1000,0)),"") -> 0–18 anos | F5: =IFERROR(INDEX(Catálogo!F$4:F$1000,MATCH($A$1&"|"&2,Índice!$A$4:$A$1000,0)),"") -> 0 | G5: =IFERROR(INDEX(Catálogo!G$4:G$1000,MATCH($A$1&"|"&2,Índice!$A$4:$A$1000,0)),"") -> 83.2 | H5: =IFERROR(INDEX(Catálogo!H$4:H$1000,MATCH($A$1&"|"&2,Índice!$A$4:$A$1000,0)),"") -> 4 | ... M5: =IFERROR(INDEX(Catálogo!M$4:M$1000,MATCH($A$1&"|"&2,Índice!$A$4:$A$1000,0)),"") -> https://correiaricardina-ui.github.io/questionarios/Anamnese_complementar_v2.html
A6: =IFERROR(INDEX(Catálogo!A$4:A$1000,MATCH($A$1&"|"&3,Índice!$A$4:$A$1000,0)),"") -> 8 | B6: =IFERROR(INDEX(Catálogo!B$4:B$1000,MATCH($A$1&"|"&3,Índice!$A$4:$A$1000,0)),"") -> Anamnese Parental Complementar | C6: =IFERROR(INDEX(Catálogo!C$4:C$1000,MATCH($A$1&"|"&3,Índice!$A$4:$A$1000,0)),"") -> Anamnese, História & Monitorização | D6: =IFERROR(INDEX(Catálogo!D$4:D$1000,MATCH($A$1&"|"&3,Índice!$A$4:$A$1000,0)),"") -> Mãe, Pai, Enc. Educação | E6: =IFERROR(INDEX(Catálogo!E$4:E$1000,MATCH($A$1&"|"&3,Índice!$A$4:$A$1000,0)),"") -> Todas as idades | F6: =IFERROR(INDEX(Catálogo!F$4:F$1000,MATCH($A$1&"|"&3,Índice!$A$4:$A$1000,0)),"") -> 0 | G6: =IFERROR(INDEX(Catálogo!G$4:G$1000,MATCH($A$1&"|"&3,Índice!$A$4:$A$1000,0)),"") -> 99 | H6: =IFERROR(INDEX(Catálogo!H$4:H$1000,MATCH($A$1&"|"&3,Índice!$A$4:$A$1000,0)),"") -> 5 | ... M6: =IFERROR(INDEX(Catálogo!M$4:M$1000,MATCH($A$1&"|"&3,Índice!$A$4:$A$1000,0)),"") -> https://correiaricardina-ui.github.io/questionarios/ANAMNESE_PARENTAL_COMPLEMENTAR_v1.html
A7: =IFERROR(INDEX(Catálogo!A$4:A$1000,MATCH($A$1&"|"&4,Índice!$A$4:$A$1000,0)),"") -> 53 | B7: =IFERROR(INDEX(Catálogo!B$4:B$1000,MATCH($A$1&"|"&4,Índice!$A$4:$A$1000,0)),"") -> Diário de Episódios | C7: =IFERROR(INDEX(Catálogo!C$4:C$1000,MATCH($A$1&"|"&4,Índice!$A$4:$A$1000,0)),"") -> Anamnese, História & Monitorização | D7: =IFERROR(INDEX(Catálogo!D$4:D$1000,MATCH($A$1&"|"&4,Índice!$A$4:$A$1000,0)),"") -> Mãe, Pai, Enc. Educação | E7: =IFERROR(INDEX(Catálogo!E$4:E$1000,MATCH($A$1&"|"&4,Índice!$A$4:$A$1000,0)),"") -> Todas as idades | F7: =IFERROR(INDEX(Catálogo!F$4:F$1000,MATCH($A$1&"|"&4,Índice!$A$4:$A$1000,0)),"") -> 0 | G7: =IFERROR(INDEX(Catálogo!G$4:G$1000,MATCH($A$1&"|"&4,Índice!$A$4:$A$1000,0)),"") -> 99 | H7: =IFERROR(INDEX(Catálogo!H$4:H$1000,MATCH($A$1&"|"&4,Índice!$A$4:$A$1000,0)),"") -> 3 | ... M7: =IFERROR(INDEX(Catálogo!M$4:M$1000,MATCH($A$1&"|"&4,Índice!$A$4:$A$1000,0)),"") -> https://correiaricardina-ui.github.io/questionarios/Diario_Episodios_v1.html
A8: =IFERROR(INDEX(Catálogo!A$4:A$1000,MATCH($A$1&"|"&5,Índice!$A$4:$A$1000,0)),"") -> 207 | B8: =IFERROR(INDEX(Catálogo!B$4:B$1000,MATCH($A$1&"|"&5,Índice!$A$4:$A$1000,0)),"") -> CGI — Escala de Impressão Clínica Global | C8: =IFERROR(INDEX(Catálogo!C$4:C$1000,MATCH($A$1&"|"&5,Índice!$A$4:$A$1000,0)),"") -> Anamnese, História & Monitorização | D8: =IFERROR(INDEX(Catálogo!D$4:D$1000,MATCH($A$1&"|"&5,Índice!$A$4:$A$1000,0)),"") -> Psicóloga, Aplicador clínico | E8: =IFERROR(INDEX(Catálogo!E$4:E$1000,MATCH($A$1&"|"&5,Índice!$A$4:$A$1000,0)),"") -> Transversal (todas as idades) | F8: =IFERROR(INDEX(Catálogo!F$4:F$1000,MATCH($A$1&"|"&5,Índice!$A$4:$A$1000,0)),"") -> 0 | G8: =IFERROR(INDEX(Catálogo!G$4:G$1000,MATCH($A$1&"|"&5,Índice!$A$4:$A$1000,0)),"") -> 99 | H8: =IFERROR(INDEX(Catálogo!H$4:H$1000,MATCH($A$1&"|"&5,Índice!$A$4:$A$1000,0)),"") -> 10 | ... M8: =IFERROR(INDEX(Catálogo!M$4:M$1000,MATCH($A$1&"|"&5,Índice!$A$4:$A$1000,0)),"") -> https://correiaricardina-ui.github.io/questionarios/CGI_v1.html
A9: =IFERROR(INDEX(Catálogo!A$4:A$1000,MATCH($A$1&"|"&6,Índice!$A$4:$A$1000,0)),"") | B9: =IFERROR(INDEX(Catálogo!B$4:B$1000,MATCH($A$1&"|"&6,Índice!$A$4:$A$1000,0)),"") | C9: =IFERROR(INDEX(Catálogo!C$4:C$1000,MATCH($A$1&"|"&6,Índice!$A$4:$A$1000,0)),"") | D9: =IFERROR(INDEX(Catálogo!D$4:D$1000,MATCH($A$1&"|"&6,Índice!$A$4:$A$1000,0)),"") | E9: =IFERROR(INDEX(Catálogo!E$4:E$1000,MATCH($A$1&"|"&6,Índice!$A$4:$A$1000,0)),"") | F9: =IFERROR(INDEX(Catálogo!F$4:F$1000,MATCH($A$1&"|"&6,Índice!$A$4:$A$1000,0)),"") | G9: =IFERROR(INDEX(Catálogo!G$4:G$1000,MATCH($A$1&"|"&6,Índice!$A$4:$A$1000,0)),"") | H9: =IFERROR(INDEX(Catálogo!H$4:H$1000,MATCH($A$1&"|"&6,Índice!$A$4:$A$1000,0)),"") | ... M9: =IFERROR(INDEX(Catálogo!M$4:M$1000,MATCH($A$1&"|"&6,Índice!$A$4:$A$1000,0)),"")
A10: =IFERROR(INDEX(Catálogo!A$4:A$1000,MATCH($A$1&"|"&7,Índice!$A$4:$A$1000,0)),"") | B10: =IFERROR(INDEX(Catálogo!B$4:B$1000,MATCH($A$1&"|"&7,Índice!$A$4:$A$1000,0)),"") | C10: =IFERROR(INDEX(Catálogo!C$4:C$1000,MATCH($A$1&"|"&7,Índice!$A$4:$A$1000,0)),"") | D10: =IFERROR(INDEX(Catálogo!D$4:D$1000,MATCH($A$1&"|"&7,Índice!$A$4:$A$1000,0)),"") | E10: =IFERROR(INDEX(Catálogo!E$4:E$1000,MATCH($A$1&"|"&7,Índice!$A$4:$A$1000,0)),"") | F10: =IFERROR(INDEX(Catálogo!F$4:F$1000,MATCH($A$1&"|"&7,Índice!$A$4:$A$1000,0)),"") | G10: =IFERROR(INDEX(Catálogo!G$4:G$1000,MATCH($A$1&"|"&7,Índice!$A$4:$A$1000,0)),"") | H10: =IFERROR(INDEX(Catálogo!H$4:H$1000,MATCH($A$1&"|"&7,Índice!$A$4:$A$1000,0)),"") | ... M10: =IFERROR(INDEX(Catálogo!M$4:M$1000,MATCH($A$1&"|"&7,Índice!$A$4:$A$1000,0)),"")
A11: =IFERROR(INDEX(Catálogo!A$4:A$1000,MATCH($A$1&"|"&8,Índice!$A$4:$A$1000,0)),"") | B11: =IFERROR(INDEX(Catálogo!B$4:B$1000,MATCH($A$1&"|"&8,Índice!$A$4:$A$1000,0)),"") | C11: =IFERROR(INDEX(Catálogo!C$4:C$1000,MATCH($A$1&"|"&8,Índice!$A$4:$A$1000,0)),"") | D11: =IFERROR(INDEX(Catálogo!D$4:D$1000,MATCH($A$1&"|"&8,Índice!$A$4:$A$1000,0)),"") | E11: =IFERROR(INDEX(Catálogo!E$4:E$1000,MATCH($A$1&"|"&8,Índice!$A$4:$A$1000,0)),"") | F11: =IFERROR(INDEX(Catálogo!F$4:F$1000,MATCH($A$1&"|"&8,Índice!$A$4:$A$1000,0)),"") | G11: =IFERROR(INDEX(Catálogo!G$4:G$1000,MATCH($A$1&"|"&8,Índice!$A$4:$A$1000,0)),"") | H11: =IFERROR(INDEX(Catálogo!H$4:H$1000,MATCH($A$1&"|"&8,Índice!$A$4:$A$1000,0)),"") | ... M11: =IFERROR(INDEX(Catálogo!M$4:M$1000,MATCH($A$1&"|"&8,Índice!$A$4:$A$1000,0)),"")
A12: =IFERROR(INDEX(Catálogo!A$4:A$1000,MATCH($A$1&"|"&9,Índice!$A$4:$A$1000,0)),"") | B12: =IFERROR(INDEX(Catálogo!B$4:B$1000,MATCH($A$1&"|"&9,Índice!$A$4:$A$1000,0)),"") | C12: =IFERROR(INDEX(Catálogo!C$4:C$1000,MATCH($A$1&"|"&9,Índice!$A$4:$A$1000,0)),"") | D12: =IFERROR(INDEX(Catálogo!D$4:D$1000,MATCH($A$1&"|"&9,Índice!$A$4:$A$1000,0)),"") | E12: =IFERROR(INDEX(Catálogo!E$4:E$1000,MATCH($A$1&"|"&9,Índice!$A$4:$A$1000,0)),"") | F12: =IFERROR(INDEX(Catálogo!F$4:F$1000,MATCH($A$1&"|"&9,Índice!$A$4:$A$1000,0)),"") | G12: =IFERROR(INDEX(Catálogo!G$4:G$1000,MATCH($A$1&"|"&9,Índice!$A$4:$A$1000,0)),"") | H12: =IFERROR(INDEX(Catálogo!H$4:H$1000,MATCH($A$1&"|"&9,Índice!$A$4:$A$1000,0)),"") | ... M12: =IFERROR(INDEX(Catálogo!M$4:M$1000,MATCH($A$1&"|"&9,Índice!$A$4:$A$1000,0)),"")
A13: =IFERROR(INDEX(Catálogo!A$4:A$1000,MATCH($A$1&"|"&10,Índice!$A$4:$A$1000,0)),"") | B13: =IFERROR(INDEX(Catálogo!B$4:B$1000,MATCH($A$1&"|"&10,Índice!$A$4:$A$1000,0)),"") | C13: =IFERROR(INDEX(Catálogo!C$4:C$1000,MATCH($A$1&"|"&10,Índice!$A$4:$A$1000,0)),"") | D13: =IFERROR(INDEX(Catálogo!D$4:D$1000,MATCH($A$1&"|"&10,Índice!$A$4:$A$1000,0)),"") | E13: =IFERROR(INDEX(Catálogo!E$4:E$1000,MATCH($A$1&"|"&10,Índice!$A$4:$A$1000,0)),"") | F13: =IFERROR(INDEX(Catálogo!F$4:F$1000,MATCH($A$1&"|"&10,Índice!$A$4:$A$1000,0)),"") | G13: =IFERROR(INDEX(Catálogo!G$4:G$1000,MATCH($A$1&"|"&10,Índice!$A$4:$A$1000,0)),"") | H13: =IFERROR(INDEX(Catálogo!H$4:H$1000,MATCH($A$1&"|"&10,Índice!$A$4:$A$1000,0)),"") | ... M13: =IFERROR(INDEX(Catálogo!M$4:M$1000,MATCH($A$1&"|"&10,Índice!$A$4:$A$1000,0)),"")
A14: =IFERROR(INDEX(Catálogo!A$4:A$1000,MATCH($A$1&"|"&11,Índice!$A$4:$A$1000,0)),"") | B14: =IFERROR(INDEX(Catálogo!B$4:B$1000,MATCH($A$1&"|"&11,Índice!$A$4:$A$1000,0)),"") | C14: =IFERROR(INDEX(Catálogo!C$4:C$1000,MATCH($A$1&"|"&11,Índice!$A$4:$A$1000,0)),"") | D14: =IFERROR(INDEX(Catálogo!D$4:D$1000,MATCH($A$1&"|"&11,Índice!$A$4:$A$1000,0)),"") | E14: =IFERROR(INDEX(Catálogo!E$4:E$1000,MATCH($A$1&"|"&11,Índice!$A$4:$A$1000,0)),"") | F14: =IFERROR(INDEX(Catálogo!F$4:F$1000,MATCH($A$1&"|"&11,Índice!$A$4:$A$1000,0)),"") | G14: =IFERROR(INDEX(Catálogo!G$4:G$1000,MATCH($A$1&"|"&11,Índice!$A$4:$A$1000,0)),"") | H14: =IFERROR(INDEX(Catálogo!H$4:H$1000,MATCH($A$1&"|"&11,Índice!$A$4:$A$1000,0)),"") | ... M14: =IFERROR(INDEX(Catálogo!M$4:M$1000,MATCH($A$1&"|"&11,Índice!$A$4:$A$1000,0)),"")
A15: =IFERROR(INDEX(Catálogo!A$4:A$1000,MATCH($A$1&"|"&12,Índice!$A$4:$A$1000,0)),"") | B15: =IFERROR(INDEX(Catálogo!B$4:B$1000,MATCH($A$1&"|"&12,Índice!$A$4:$A$1000,0)),"") | C15: =IFERROR(INDEX(Catálogo!C$4:C$1000,MATCH($A$1&"|"&12,Índice!$A$4:$A$1000,0)),"") | D15: =IFERROR(INDEX(Catálogo!D$4:D$1000,MATCH($A$1&"|"&12,Índice!$A$4:$A$1000,0)),"") | E15: =IFERROR(INDEX(Catálogo!E$4:E$1000,MATCH($A$1&"|"&12,Índice!$A$4:$A$1000,0)),"") | F15: =IFERROR(INDEX(Catálogo!F$4:F$1000,MATCH($A$1&"|"&12,Índice!$A$4:$A$1000,0)),"") | G15: =IFERROR(INDEX(Catálogo!G$4:G$1000,MATCH($A$1&"|"&12,Índice!$A$4:$A$1000,0)),"") | H15: =IFERROR(INDEX(Catálogo!H$4:H$1000,MATCH($A$1&"|"&12,Índice!$A$4:$A$1000,0)),"") | ... M15: =IFERROR(INDEX(Catálogo!M$4:M$1000,MATCH($A$1&"|"&12,Índice!$A$4:$A$1000,0)),"")

Sheet Neurodesenvolvimento
A1: Neurodesenvolvimento | I1: =COUNTIF(Catálogo!$C$4:$C$1000,$A$1)&IF(COUNTIF(Catálogo!$C$4:$C$1000,$A$1)=1," instrumento nesta área"," instrumentos nesta área") -> 27 instrumentos nesta área
A2: Vista automática da folha «Catálogo». Não editar aqui: acrescente ou altere sempre na folha «Catálogo» e esta atualiza-se sozinha. | I2: =IF(COUNTIF(Catálogo!$C$4:$C$1000,$A$1)>29,"⚠ Área com mais instrumentos do que linhas nesta folha — alargar","OK") -> OK
A3: Nº | B3: Nome do Instrumento | C3: Área Clínica | D3: Destinatários | E3: Faixa etária | F3: Idade mín (anos) | G3: Idade máx (anos) | H3: Nº domínios | I3: Objetivo clínico | J3: Domínios / Subescalas (por extenso) | K3: syncKey (Sheet) | L3: ID interno | M3: Link
A4: =IFERROR(INDEX(Catálogo!A$4:A$1000,MATCH($A$1&"|"&1,Índice!$A$4:$A$1000,0)),"") -> 1 | B4: =IFERROR(INDEX(Catálogo!B$4:B$1000,MATCH($A$1&"|"&1,Índice!$A$4:$A$1000,0)),"") -> ABAS-3 — Auto-relato | C4: =IFERROR(INDEX(Catálogo!C$4:C$1000,MATCH($A$1&"|"&1,Índice!$A$4:$A$1000,0)),"") -> Neurodesenvolvimento | D4: =IFERROR(INDEX(Catálogo!D$4:D$1000,MATCH($A$1&"|"&1,Índice!$A$4:$A$1000,0)),"") -> Paciente | E4: =IFERROR(INDEX(Catálogo!E$4:E$1000,MATCH($A$1&"|"&1,Índice!$A$4:$A$1000,0)),"") -> 16–89 anos | F4: =IFERROR(INDEX(Catálogo!F$4:F$1000,MATCH($A$1&"|"&1,Índice!$A$4:$A$1000,0)),"") -> 16 | G4: =IFERROR(INDEX(Catálogo!G$4:G$1000,MATCH($A$1&"|"&1,Índice!$A$4:$A$1000,0)),"") -> 99 | H4: =IFERROR(INDEX(Catálogo!H$4:H$1000,MATCH($A$1&"|"&1,Índice!$A$4:$A$1000,0)),"") -> 4 | ... M4: =IFERROR(INDEX(Catálogo!M$4:M$1000,MATCH($A$1&"|"&1,Índice!$A$4:$A$1000,0)),"") -> https://correiaricardina-ui.github.io/questionarios/ABAS3_Autorrelato_v1.html
A5: =IFERROR(INDEX(Catálogo!A$4:A$1000,MATCH($A$1&"|"&2,Índice!$A$4:$A$1000,0)),"") -> 2 | B5: =IFERROR(INDEX(Catálogo!B$4:B$1000,MATCH($A$1&"|"&2,Índice!$A$4:$A$1000,0)),"") -> ABAS-3 — Educador (0–5) | C5: =IFERROR(INDEX(Catálogo!C$4:C$1000,MATCH($A$1&"|"&2,Índice!$A$4:$A$1000,0)),"") -> Neurodesenvolvimento | D5: =IFERROR(INDEX(Catálogo!D$4:D$1000,MATCH($A$1&"|"&2,Índice!$A$4:$A$1000,0)),"") -> Educador(a) | E5: =IFERROR(INDEX(Catálogo!E$4:E$1000,MATCH($A$1&"|"&2,Índice!$A$4:$A$1000,0)),"") -> 0–5 anos | F5: =IFERROR(INDEX(Catálogo!F$4:F$1000,MATCH($A$1&"|"&2,Índice!$A$4:$A$1000,0)),"") -> 0 | G5: =IFERROR(INDEX(Catálogo!G$4:G$1000,MATCH($A$1&"|"&2,Índice!$A$4:$A$1000,0)),"") -> 5.9 | H5: =IFERROR(INDEX(Catálogo!H$4:H$1000,MATCH($A$1&"|"&2,Índice!$A$4:$A$1000,0)),"") -> 4 | ... M5: =IFERROR(INDEX(Catálogo!M$4:M$1000,MATCH($A$1&"|"&2,Índice!$A$4:$A$1000,0)),"") -> https://correiaricardina-ui.github.io/questionarios/ABAS3_PreEscolar_Educador.html
